Workbook
Name _ANN10: 'COTIZACIÓN '!#REF!
Name _ANN10: 'COTIZACION (Financ)'!#REF!
Name _ANN10: #REF!
Name _ANN20: 'COTIZACIÓN '!#REF!
Name _ANN20: 'COTIZACION (Financ)'!#REF!
Name _ANN20: #REF!
Name a: 'COTIZACIÓN '!#REF!
Name a: 'COTIZACION (Financ)'!#REF!
Name a: #REF!
Name aa: #REF!
Name activo: '[1]B$E'!$D$48
Name activoc: '[1]B$E'!$D$11
Name activof: '[1]B$E'!$D$30
Name Años_préstamo: '[2]Ptmo P'!$D$7
Name Años_préstamo: '[2]Ptmo P'!$D$7
Name Años_préstamo: #REF!
Name Años_préstamo: '[2]Ptmo P'!$D$7
Name Años_préstamo: #REF!
Name Años_préstamo: #REF!
Name Años_préstamo: #REF!
Name Area: [3]!Tabla1[area]
Name b: 'COTIZACIÓN '!#REF!
Name b: 'COTIZACION (Financ)'!#REF!
Name b: #REF!
Name Beginning_Balance: -FV(Interest_Rate/12,'COTIZACIÓN '!Payment_Number-1,-'COTIZACIÓN '!Monthly_Payment,Loan_Amount)
Name Beginning_Balance: -FV([0]!Interest_Rate/12,'COTIZACION (Financ)'!Payment_Number-1,-'COTIZACION (Financ)'!Monthly_Payment,[0]!Loan_Amount)
Name Beginning_Balance: -FV(Interest_Rate/12,Payment_Number-1,-Monthly_Payment,Loan_Amount)
Name Cap_Base: [4]Performance!$D$24
Name Cap_kW: [5]Variables!$B$25
Name Capital: '[2]Ptmo P'!$G$18:$G$497
Name Capital: '[2]Ptmo P'!$G$18:$G$497
Name Capital: #REF!
Name Capital: '[2]Ptmo P'!$G$18:$G$497
Name Capital: #REF!
Name Capital: #REF!
Name Capital: #REF!
Name capsocial: '[1]B$E'!$H$44
Name CF_OM_Bz: '[6]O&M'!#REF!
Name CF_OM_US: '[6]O&M'!#REF!
Name Clientes: '[1]B$E'!$B$14
Name Cum_Cash_Flow: [6]CF!#REF!
Name Datos: 'COTIZACIÓN '!#REF!
Name Datos: 'COTIZACION (Financ)'!#REF!
Name Datos: #REF!
Name Datos: #REF!
Name Datos: #REF!
Name Demanda_Máxima_kW: [5]Variables!$B$7
Name Día_de_pago: #N/A
Name Día_de_pago: #N/A
Name Día_de_pago: #N/A
Name Día_de_pago: #N/A
Name Día_de_pago: DATE(YEAR([0]!Inicio_prestamo),MONTH([0]!Inicio_prestamo)+Payment_Number,DAY([0]!Inicio_prestamo))
Name Día_de_pago: DATE(YEAR([0]!Inicio_prestamo),MONTH([0]!Inicio_prestamo)+Payment_Number,DAY([0]!Inicio_prestamo))
Name Día_de_pago: DATE(YEAR([0]!Inicio_prestamo),MONTH([0]!Inicio_prestamo)+Payment_Number,DAY([0]!Inicio_prestamo))
Name Día_de_pago: DATE(YEAR([0]!Inicio_prestamo),MONTH([0]!Inicio_prestamo)+Payment_Number,DAY([0]!Inicio_prestamo))
Name Día_de_pago: DATE(YEAR([0]!Inicio_prestamo),MONTH([0]!Inicio_prestamo)+Payment_Number,DAY([0]!Inicio_prestamo))
Name Día_de_pago: DATE(YEAR([0]!Inicio_prestamo),MONTH([0]!Inicio_prestamo)+Payment_Number,DAY([0]!Inicio_prestamo))
Name Día_de_pago: DATE(YEAR([0]!Inicio_prestamo),MONTH([0]!Inicio_prestamo)+Payment_Number,DAY([0]!Inicio_prestamo))
Name Día_de_pago: DATE(YEAR([0]!Inicio_prestamo),MONTH([0]!Inicio_prestamo)+Payment_Number,DAY([0]!Inicio_prestamo))
Name Día_de_pago: DATE(YEAR([0]!Inicio_prestamo),MONTH([0]!Inicio_prestamo)+Payment_Number,DAY([0]!Inicio_prestamo))

Sheet LEEME
B1: MATRIZ Y OFERTA
B2: Leer esto primero. Son cinco minutos y evitan los errores que mas caro salen.
B4: QUE ES ESTE ARCHIVO
B5: Es el machote oficial de matriz de costo y oferta. No se trabaja sobre el original: se copia una vez a la carpeta Matriz-Oferta de la cotizacion, y se llena esa copia.
B6: Tiene 34 pestanas: 14 de trabajo, 4 de guia (esta y las tres del final) y 16 ocultas. Las ocultas son estructura de reserva y hojas de analisis que hoy no se usan.
B8: LA REGLA DE ORO
B9: En cada pestana de producto se escriben CUATRO columnas. Todo lo demas son formulas que calculan solas.
B10: Si al escribir en una celda cambia un numero en otra, esa otra es formula: no la toques ni la pises.
B11: Nunca escribas un precio de venta a mano. El precio de venta SALE del costo, no al reves.
B13: EN QUE ORDEN SE LLENA
B14: 1. Datos del proyecto | C14: La ultima pestana antes de las guias. Cliente, tipo de cotizacion, regimen fiscal, porcentajes y financiamiento.
B15: 2. Equipos | C15: Las lineas de equipo que se van a vender. Es la pestana principal.
B16: 3. MATERIALES | C16: Materiales de instalacion, si el alcance los incluye.
B17: 4. MANO DE OBRA y Transporte | C17: Solo si la oferta incluye instalacion.
B18: 5. Financiamiento | C18: Solo si el proyecto lleva esa modalidad. Si no, se deja en blanco y no pasa nada.
B19: 6. COTIZACION | C19: No se escribe: se revisa. Es lo que ve el cliente.
B21: LAS UNICAS CUATRO COLUMNAS QUE SE ESCRIBEN
B22: Columna | C22: Que va ahi, y con que cuidado
B23: Description | C23: Marca + modelo + descripcion del catalogo. Se copia tal cual a la cotizacion, asi que tiene que entenderse del lado del cliente.
B24: IMPORTADO | C24: si / no, segun si Grupo Vision compra ese articulo fuera del pais. NO es donde se fabrica: una camara coreana comprada a un proveedor tico es 'no'. Una linea de flete va siempre como 'no': si va 'si', se le cobra transporte al transporte.
B25: Qty | C25: Cuantas unidades pide el proyecto. Si no la sabes, preguntala. No la estimes.
B26: Costo Unit | C26: Lo que Grupo Vision PAGA por una unidad, en dolares: la columna Precio de compra GV del catalogo (el precio dealer). Si la fila no tiene costo, se usa el precio de lista y se avisa, porque ahi el margen real queda mayor que el que muestra la matriz. NUNCA el MSRP como costo.
B28: LOS CUATRO ERRORES QUE MAS CARO SALEN
B29: 1. Poner el MSRP como costo | C29: La cotizacion sale cerca del DOBLE. El MSRP es donde suele terminar el precio al cliente, no de donde arranca el calculo. Medido: en 57.607 lineas de 1.119 cotizaciones reales, nadie lo hizo nunca.
B30: 2. Poner mal IMPORTADO | C30: Medido: sobre 10 unidades de 100 dolares, la diferencia entre 'si' y 'no' es de 387,24 dolares, un 26,5%. Excel no muestra ningun error.
B31: 3. Confundir los dos IVA | C31: El IVA de la columna es un COSTO: lo que el proveedor nos cobra a nosotros al comprar. El impuesto del cliente es la fila IMPUESTO de COTIZACION, y depende del regimen fiscal del cliente.
B32: 4. Cambiar el margen en Equipos | C32: El margen de OPEX GV es la formula =Equipos!N4. Si cambias el margen en Equipos, tambien se mueve el de OPEX GV, sin ningun aviso.
B33: LAS OTRAS TRES GUIAS, AL FINAL DEL LIBRO
B34: Guia de pestanas | C34: Que hace cada pestana de trabajo, que se escribe a mano y que sale solo.
B35: Guia de formulas | C35: Las formulas que deciden la plata, explicadas en palabras.

Sheet CCTV DISEÑO
B1: Description | C1: Qty | J1: Ancho de Banda
B2: Sistema CCTV Perímetro | E2: No. | F2: Modelo | G2: Tipo | H2: Resolución | I2: Cantidad | J2: Visualización | K2: Grabación | L2: LPR | M2: Reconocimiento Facial | N2: Conteo | O2: Total | P2: Analíticas
B3: Cámara fija IP para Perimetro Exterior Modelo: XNV-6080R | C3: 48 | E3: 1 | F3: XNV-6080R | G3: Domo Exterior | H3: 2MP | J3: 77.35 Mbps | K3: 168.76 Mbps | O3: 246.10 Mbps | P3: • Manipulación • Merodeo • Detección direccional, • Detección de desenfoque, • Detección de empañamiento, • Línea virtual, entrada y salida, (des)aparición, • Detección de audio, • Detección de rostros, • Detección de movimiento, • Seguimiento automático digital, • Clasificación de sonidos
B4: Cámara fija IP para Perimetro Interior Modelo: XND-6080RV | C4: 30 | E4: 2 | F4: XND-6080RV | G4: Domo Interior | H4: 2MP | J4: 204.25 Mbps | K4: 445.64 Mbps | O4: 649.90 Mbps | P4: • Manipulación, • Merodeo, • Detección direccional, • Detección de desenfoque, • Detección de empañamiento, • Línea virtual, entrada y salida, (des)aparición, • Detección de audio, • Detección de rostros, • Detección de movimiento, • Seguimiento automático digital, • Clasificación de sonidos
B5: Cámara fija IP para Estacionamientos Modelo: XNO-6080R | C5: 15 | E5: 3 | F5: XNO-6080R | G5: Bullet Exterior | H5: 2MP | J5: 22.12 Mbps | K5: 44.24 Mbps | O5: 66.36 Mbps | P5: • Manipulación, • Merodeo, • Detección direccional, • Detección de desenfoque, • Detección de empañamiento, • Línea virtual, entrada y salida, (des)aparición, • Detección de audio, • Detección de rostros, • Detección de movimiento, • Seguimiento automático digital, • Clasificación de sonidos
B6: Cámara fija IP para Reconocimiento Modelo: XNO-6080R | C6: 12 | E6: 4 | F6: PNM-9020V | G6: Panoramica Multi-sensor 180˚ | H6: 7.3MP | J6: 6.76 Mbps | K6: 51.61 Mbps | O6: 58.37 Mbps | P6: • Manipulación, • Línea virtual, entrada / salida, aparecer / desaparecer, • Detección de audio, • Detección de desenfoque, • Seguimiento automático digital, • Mapa de calor
B7: Cámara fija IP Panoramica 180° Modelo: PNM-9020V | C7: 9 | E7: 5 | F7: PNM-9000VQ | G7: Panoramica Multi-directional 360° | H7: 8MP | J7: 81.10 Mbps | K7: 176.95 Mbps | O7: 258.05 Mbps | P7: • Manipulación, • Merodeo, • Detección direccional, • Detección de empañamiento, • Línea virtual, entrada y salida, (des)aparición, • Detección facial, • Detección de movimiento, • Detección de desenfoque
B8: Camara fija IP Panoramica 360° Modelo: PNM-9000VQ | C8: 20 | E8: 6 | F8: PNM-9320VQP | G8: Panoramica Multi-directional 360° + PTZ | H8: 10MP | J8: 172.71 Mbps | K8: 282.62 Mbps | O8: 455.34 Mbps | P8: • Adulteración, • Ociosidad, • Detección direccional, • Detección de neblina, • Línea virtual, entradas y salidas, apariciones y desapariciones, • Detección facial, • Detección de movimiento, • Detección de desenfoque (cámara multidireccional)
B9: Camara IP Panoramica 360°/PTZ Modelo: PNM-9320VQP | C9: 14 | E9: 7 | F9: XNP-6320H | G9: Domo PTZ Exterior | H9: 2MP | J9: 14.27 Mbps | K9: 31.13 Mbps | O9: 45.40 Mbps | P9: • Manipulación, • Merodeo, • Detección de dirección, • Detección de niebla, • Línea virtual, entrada y salida, (Des) aparece, • Detección de audio, • Detección de rostros, • Detección de movimiento, • Clasificación de sonidos
B10: Camara IP PTZ Perimetral Modelo: XNP-6320H | C10: 19 | E10: 8 | F10: XNP-6320 | G10: Domo PTZ Interior | H10: 2MP | J10: 1.50 Mbps | K10: 3.28 Mbps | O10: 4.78 Mbps | P10: • Manipulación, • Merodeo, • Detección de dirección, • Detección de niebla, • Línea virtual, entrada y salida, (Des) aparece, • Detección de audio, • Detección de rostros, • Detección de movimiento, • Clasificación de sonidos
B11: Sistema CCTV Terminal | E11: 9 | F11: XNF-8010R | G11: Panoramica 360° Fisheye | H11: 6MP | J11: 39.42 Mbps | K11: 77.41 Mbps | O11: 116.84 Mbps | P11: • Manipulación, • Merodeo, • Detección de dirección, • Línea virtual, entrada y salida, (des) aparece, • Detección de audio, • Clasificación de sonidos, • Conteo de personas, • Mapa de calor, • Gestión de colas
B12: Camara IP Visualizacion Interior Modelo: XND-6080RV | C12: 242
B13: Camara IP Visualizacion Exterior Modelo: XNV-6080R | C13: 55
B14: Camara IP 360°/PTZ Interior Modelo: PNM-9320VQP | C14: 7 | F14: Notas:
B15: Camara IP 360°/PTZ Exterior Modelo: PNM-9320VQP | C15: 2 | G15: • Se recomienda la configuración de una red Multicast para la optimización de los streams de video demandados a cada cámara.
B16: Camara IP Panoramicas 360° Interior Modelo: XNF-8010R | C16: 21
B17: Camara IP Panoramica 360° Exterior Modelo: PNM-9000VQ | C17: 7
B18: Camara IP PTZ Modelo: XNP-6320 | C18: 2 | F18: Accesorios por Modelo
B19: Camara para Ascensores Modelo: XND-6010 | C19: 6 | F19: Accesorios por Modelo | J19: Resumen
F20: Cámara | G20: Accesorios | H20: Cantidad | J20: No. | K20: Modelo | L20: Cantidad
F21: XNV-6080R | G21: Hanging Mount Modelo: SBP-300HM6 | H21: 50 | J21: 1 | K21: 1.5" Coupler Modelo: SBP-HCF | M21: 95 | N21: 1.5" Coupler Modelo: SBP-HCF
F22: 103 | G22: Parapet Mount Modelo: SBP-300LM | J22: 2 | K22: Back Box Modelo: SBP-302CMB | M22: 9 | N22: 1.5" Coupler Modelo: SBP-HCF
G23: Hanging Mount Modelo: SBP-300HM6 | J23: 3 | K23: Flush Mount Modelo: SHD-3000F1 | M23: 15 | N23: 1.5" Coupler Modelo: SBP-HCF
G24: Wall Mount Arm Modelo: SBP-390WM1 | J24: 4 | K24: Hanging Mount Modelo: SBP-201HM | M24: 10 | N24: 1.5" Coupler Modelo: SBP-HCF
G25: Installation Box Modelo: SBP-300NB | J25: 5 | K25: Hanging Mount Modelo: SBP-276HM | M25: 10 | N25: 1.5" Coupler Modelo: SBP-HCF
F26: XND-6080RV | G26: Hanging Mount Modelo: SBP-300HM6 | H26: 95 | J26: 6 | K26: Hanging Mount Modelo: SBP-300HM5 | M26: 10 | N26: 1.5" Coupler Modelo: SBP-HCF
F27: 272 | G27: 1.5" Coupler Modelo: SBP-HCF | J27: 7 | K27: Hanging Mount Modelo: SBP-300HM6 | M27: 95 | N27: Back Box Modelo: SBP-302CMB
G28: Back Box Modelo: SBP-302CMB | J28: 8 | K28: Installation Box Modelo: SBP-300NB | M28: 9 | N28: Back Box Modelo: SBP-302CMB
G29: Flush Mount Modelo: SHD-3000F1 | J29: 9 | K29: Lentes 2M 2.8mm Modelo: SLA-2M2800P | M29: 15 | N29: Back Box Modelo: SBP-302CMB
G30: Hanging Mount Modelo: SBP-300HM6 | J30: 10 | K30: Lentes 2M 2.8mm Modelo: SLA-2M2800Q | M30: 10 | N30: Back Box Modelo: SBP-302CMB
G31: Wall Mount Arm Modelo: SBP-390WM1 | J31: 11 | K31: Parapet Mount Modelo: SBP-300LM | M31: 10 | N31: Back Box Modelo: SBP-302CMB
G32: Installation Box Modelo: SBP-300NB | J32: 12 | K32: Pole Mount Modelo: SBP-300PM | M32: 10 | N32: Back Box Modelo: SBP-302CMB
F33: XNO-6080R | G33: Pole Mount Modelo: SBP-302PM | H33: 27 | J33: 13 | K33: Pole Mount Modelo: SBP-302PM | M33: 95 | N33: Flush Mount Modelo: SHD-3000F1
F34: PNM-9020V | G34: Hanging Mount Modelo: SBP-201HM | H34: 9 | J34: 14 | K34: Wall Mount Arm Modelo: SBP-390WM1 | M34: 9 | N34: Hanging Mount Modelo: SBP-201HM
F35: 9 | G35: 1.5" Coupler Modelo: SBP-HCF | M35: 15 | N35: Hanging Mount Modelo: SBP-276HM
G36: Back Box Modelo: SBP-302CMB | M36: 12 | N36: Hanging Mount Modelo: SBP-276HM
F37: PNM-9000VQ | G37: Hanging Mount Modelo: SBP-276HM | H37: 15 | M37: 10 | N37: Hanging Mount Modelo: SBP-300HM5
F38: 27 | G38: 1.5" Coupler Modelo: SBP-HCF | M38: 11 | N38: Hanging Mount Modelo: SBP-300HM5
G39: Back Box Modelo: SBP-302CMB | M39: 50 | N39: Hanging Mount Modelo: SBP-300HM6
G40: Hanging Mount Modelo: SBP-276HM | M40: 53 | N40: Hanging Mount Modelo: SBP-300HM6
...

Sheet Evaluacion TIR-VAN
B3: Flujo de Caja | F3: 60 meses
G4: 2020 | H4: 2021 | I4: 2022 | J4: 2023 | K4: 2024 | L4: 2024
B5: Ingresos
B6: Ingresos Operativos | C6: USDk | G6: 0 | H6: 0 | I6: =+H6 -> 0 | J6: =+I6 -> 0 | K6: =+J6 -> 0
B8: Costos
B9: COGS | C9: USDk | G9: 0 | H9: 0 | I9: =+H9 -> 0 | J9: =+I9 -> 0 | K9: =+J9 -> 0
B10: Costos Variables | C10: USDk | G10: =-RESUMEN!C19 -> 0 | H10: 0 | I10: 0 | J10: 0 | K10: 0
B11: OPEX | C11: USDk | G11: 0 | H11: =-(SUM(RESUMEN!C10:C11)+RESUMEN!C18)/4 -> 0 | I11: =+H11 -> 0 | J11: =+I11 -> 0 | K11: =+J11 -> 0
B12: Otros gastos (incluye depreciaciones) | C12: USDk | G12: 0
B13: (-) Depreciaciones y amortizaciones | C13: USDk | G13: 0 | H13: 0 | I13: =+H13 -> 0 | J13: =+I13 -> 0 | K13: =+J13 -> 0
B14: Otros Ingresos | C14: USDk | G14: 0 | H14: 0 | I14: 0 | J14: 0 | K14: 0
B16: Impuestos | C16: USDk | G16: 0 | H16: =-SUM(H6:H14)*0.3 -> 0 | I16: =-SUM(I6:I14)*0.3 -> 0 | J16: =-SUM(J6:J14)*0.3 -> 0 | K16: =-SUM(K6:K14)*0.3 -> 0
B18: Flujo de Caja Operativo | C18: USDk | G18: =SUM(G6:G16) -> 0 | H18: =SUM(H6:H16) -> 0 | I18: =SUM(I6:I16) -> 0 | J18: =SUM(J6:J16) -> 0 | K18: =SUM(K6:K16) -> 0
B20: Inversiones
B21: Capex | C21: USDk | G21: 0 | H21: 0 | I21: 0 | J21: 0 | K21: 0
B22: Ajuste de Flujo | C22: USDk | H22: =H9*-1 -> 0 | I22: =I9*-1 -> 0 | J22: =J9*-1 -> 0 | K22: =K9*-1 -> 0
B23: Flujo de Caja de Inversión | C23: USDk | G23: =SUM(G21:G22) -> 0 | H23: =SUM(H21:H22) -> 0 | I23: =SUM(I21:I22) -> 0 | J23: =SUM(J21:J22) -> 0 | K23: =SUM(K21:K22) -> 0
B25: Financiamiento Adicional
B26: Capital Adicional | C26: USDk | G26: 0 | H26: 0 | I26: 0 | J26: 0 | K26: 0
B27: Total | C27: USDk | G27: =SUM(G26:G26) -> 0 | H27: =SUM(H26:H26) -> 0 | I27: =SUM(I26:I26) -> 0 | J27: =SUM(J26:J26) -> 0 | K27: =SUM(K26:K26) -> 0
B29: Flujo de caja disponible para servicio de Deuda | C29: USDk | G29: =G18+G23+G27 -> 0 | H29: =H18+H23+H27 -> 0 | I29: =I18+I23+I27 -> 0 | J29: =J18+J23+J27 -> 0 | K29: =K18+K23+K27 -> 0
B31: Servicio de Deuda
B32: Intereses | C32: USDk | G32: 0 | H32: 0 | I32: 0 | J32: 0 | K32: 0
B33: Principal | C33: USDk | G33: 0 | H33: 0 | I33: 0 | J33: 0 | K33: 0
B34: Total | C34: USDk | G34: =SUM(G32:G33) -> 0 | H34: =SUM(H32:H33) -> 0 | I34: =SUM(I32:I33) -> 0 | J34: =SUM(J32:J33) -> 0 | K34: =SUM(K32:K33) -> 0
B36: Flujo de Caja Neto | C36: USDk | G36: =G29+G34 -> 0 | H36: =H29+H34 -> 0 | I36: =I29+I34 -> 0 | J36: =J29+J34 -> 0 | K36: =K29+K34 -> 0
B38: Balance De Caja Inicial | C38: USDk | G38: 0 | H38: =G39 -> 0 | I38: =H39 -> 0 | J38: =I39 -> 0 | K38: =J39 -> 0
B39: Balance De Caja Final | C39: USDk | G39: =+G36+G38 -> 0 | H39: =+H36+H38 -> 0 | I39: =+I36+I38 -> 0 | J39: =+J36+J38 -> 0 | K39: =+K36+K38 -> 0
B40: Flujo acumulado | C40: # | G40: =+G39 -> 0 | H40: =+H39 -> 0 | I40: =+I39 -> 0 | J40: =+J39 -> 0 | K40: =+K39 -> 0
G41: 0 | H41: 1 | I41: 2 | J41: 3 | K41: 4
B42: Tasa de descuento | G42: 0 | H42: =G42 -> 0 | I42: =H42 -> 0 | J42: =I42 -> 0 | K42: =J42 -> 0
B43: Flujo descontado | G43: =+G36 -> 0 | H43: =H36/(1+H$42)^H41 -> 0 | I43: =I36/(1+I$42)^I41 -> 0 | J43: =J36/(1+J$42)^J41 -> 0 | K43: =K36/(1+K$42)^K41 -> 0
B44: VAN | F44: =+SUM(G43:L43) -> 0
B45: TIR | F45: =IFERROR(+IRR(G36:L36),"")
H46: =H43 -> 0 | I46: =I43 -> 0 | J46: =J43 -> 0 | K46: =K43 -> 0
H47: =SUM(H46:L46) -> 0

Sheet Resumen por Servicio
B1: Resumen de Costos por Servicio
B2: RESUMEN DE PROYECTO - CCTV
B3: Resumen del Proyecto | C3: Cantidad total para proyecto | D3: Costo Unitario | E3: Costo total | F3: % del costo | G3: Venta Unitario | H3: P. Venta total | I3: Costo Mensual (4 años) | J3: Venta mensual (4 años) Unitaria | K3: Venta mensual total | L3: Precio venta Ofertado unitario | M3: Precio venta total
B4: Cámaras PTZ | F4: =IFERROR(E4/$E$14,"")
B5: Cámaras Bullet | F5: =IFERROR(E5/$E$14,"")
B6: Centro de Monitoreo | F6: =IFERROR(E6/$E$14,"")
B7: Almacenamiento | F7: =IFERROR(E7/$E$14,"")
B8: VMS | F8: =IFERROR(E8/$E$14,"")
B9: Fibra optica | F9: =IFERROR(E9/$E$14,"")
B10: Gabinetes y paneles | F10: =IFERROR(E10/$E$14,"")
B11: Postes | F11: =IFERROR(E11/$E$14,"")
B12: Cámaras LPR | F12: =IFERROR(E12/$E$14,"")
B13: Control de Acceso | F13: =IFERROR(E13/$E$14,"")
B14: TOTALES
B17: Servicio | C17: Porcentaje de margen con financiamiento (unitario)
B18: Cámaras PTZ | C18: =IFERROR((J4-I4)/J4,"")
B19: Cámaras Bullet | C19: =IFERROR((J5-I5)/J5,"")
B20: Centro de Monitoreo | C20: =IFERROR((J6-I6)/J6,"")
B21: Almacenamiento | C21: =IFERROR((J7-I7)/J7,"")
B22: VMS | C22: =IFERROR((J8-I8)/J8,"")
B23: Fibra optica | C23: =IFERROR((J9-I9)/J9,"")
B24: Gabinetes y paneles | C24: =IFERROR((J10-I10)/J10,"")
B25: Postes | C25: =IFERROR((J11-I11)/J11,"")
B26: Cámaras LPR | C26: =IFERROR((J12-I12)/J12,"")
B27: Control de Acceso | C27: =IFERROR((J13-I13)/J13,"")
B30: Oferta Version 2 | C30: Oferta Version 1
A31: Costo | C31: 477579.73
A32: Venta sin impuesto | C32: 676559.19
A33: Margen | B33: =IFERROR((B32-B31)/B32,"")
A34: Cuota por financiamiento | C34: 33773.639
A35: Numero de cuotas | B35: 48 | C35: 48
A36: Venta financiada
A37: Utilidad esperada | C37: 1004708.1
C38: Utilidad de proyecto

Sheet RESUMEN
B1: Resumen de Costos por Componente | F1: Tasa $ | G1: 25
B2: RESUMEN DE PROYECTO - CCTV | J2: OPCIÓN DE SERVICIOS POR 4 AÑOS
B3: Resumen del Proyecto | C3: Costo | D3: % del costo | E3: % de venta | F3: P. Venta | G3: Margen X Componente | J3: Monto | K3: =+F12 -> 0 | L3: Int.s | M3: 0.1
A4: CCTV | B4: =Equipos!B3 -> Productos 1 | C4: =+Equipos!M57 -> 0 | D4: =IFERROR(C4/$C$12,"") | E4: =+Equipos!N4 -> 0.274 | F4: =Tabla2[[#This Row],[Costo]]/(1-Tabla2[[#This Row],[% de venta]]) -> 0 | G4: =+Tabla2[[#This Row],[P. Venta ]]-Tabla2[[#This Row],[Costo]] -> 0 | J4: Plazo | K4: 48
B5: =+'Productos 2'!A3 -> Productos 2 | C5: =+'Productos 2'!L17 -> 0 | D5: =IFERROR(C5/$C$12,"") | E5: =+'Productos 2'!M4 -> 0.3 | F5: =Tabla2[[#This Row],[Costo]]/(1-Tabla2[[#This Row],[% de venta]]) -> 0 | G5: =+Tabla2[[#This Row],[P. Venta ]]-Tabla2[[#This Row],[Costo]] -> 0 | J5: Cuota | K5: =PMT(M3/12,K4,-K3) -> 0
B6: =+'Productos 3'!A3 -> Productos 3 | C6: =+'Productos 3'!L22 -> 0 | D6: =IFERROR(C6/$C$12,"") | E6: =+'Productos 3'!M4 -> 0.3 | F6: =Tabla2[[#This Row],[Costo]]/(1-Tabla2[[#This Row],[% de venta]]) -> 0 | G6: =+Tabla2[[#This Row],[P. Venta ]]-Tabla2[[#This Row],[Costo]] -> 0 | J6: TIR | K6: =IFERROR('Evaluacion TIR-VAN'!F45,"")
B7: =+'Productos 4'!A3 -> Productos 4 | C7: =+'Productos 4'!L21 -> 0 | D7: =IFERROR(C7/$C$12,"") | E7: =+'Productos 4'!M4 -> 0.3 | F7: =Tabla2[[#This Row],[Costo]]/(1-Tabla2[[#This Row],[% de venta]]) -> 0 | G7: =+Tabla2[[#This Row],[P. Venta ]]-Tabla2[[#This Row],[Costo]] -> 0 | J7: Utilidad Neta del Ejercicio | L7: ='Evaluacion TIR-VAN'!H47 -> 0 | M7: =IFERROR(L7/K3,"")
B8: =+'Productos 5'!A3 -> Productos 5 | C8: =+'Productos 5'!L25 -> 0 | D8: =IFERROR(C8/$C$12,"") | E8: =+'Productos 5'!M4 -> 0.3 | F8: =Tabla2[[#This Row],[Costo]]/(1-Tabla2[[#This Row],[% de venta]]) -> 0 | G8: =+Tabla2[[#This Row],[P. Venta ]]-Tabla2[[#This Row],[Costo]] -> 0
A9: Materiales/otros | B9: =+MATERIALES!A3 -> Materiales | C9: =+MATERIALES!L46 -> 0 | D9: =IFERROR(C9/$C$12,"") | E9: =+MATERIALES!M4 -> 0.3 | F9: =Tabla2[[#This Row],[Costo]]/(1-Tabla2[[#This Row],[% de venta]]) -> 0 | G9: =+Tabla2[[#This Row],[P. Venta ]]-Tabla2[[#This Row],[Costo]] -> 0
B10: =+'OPEX GV'!A3 -> OPEX GV | C10: 0 | D10: =IFERROR(C10/$C$12,"") | E10: =+'OPEX GV'!M4 -> 0.274 | F10: =Tabla2[[#This Row],[Costo]]/(1-Tabla2[[#This Row],[% de venta]]) -> 0 | G10: =+Tabla2[[#This Row],[P. Venta ]]-Tabla2[[#This Row],[Costo]] -> 0
A11: OPEX | B11: =+'OPEX Proyecto'!A3 -> OPEX | C11: 0 | D11: =IFERROR(C11/$C$12,"") | E11: =+'OPEX Proyecto'!M4 -> 0.3 | F11: =Tabla2[[#This Row],[Costo]]/(1-Tabla2[[#This Row],[% de venta]]) -> 0 | G11: =+Tabla2[[#This Row],[P. Venta ]]-Tabla2[[#This Row],[Costo]] -> 0
B12: TOTALES | C12: =SUBTOTAL(109,C4:C11) -> 0 | D12: =SUBTOTAL(109,D4:D11) -> 0 | E12: =+AVERAGE(E4:E11) -> 0.2935 | F12: =SUBTOTAL(109,F4:F11) -> 0 | G12: =SUBTOTAL(109,G4:G11) -> 0
B15: Ingresos | C15: =F12 -> 0
B16: Costos | C16: =C12 -> 0
B17: Margen bruto | C17: =C15-C16 -> 0
B18: Opex | C18: =C11 -> 0
B19: Opex administrativo
B20: Comisiones | C20: =C15*3% -> 0
B21: Utilidad Operativa | C21: =+C17-SUM(C18:C20) -> 0
B22: Fianzas | C22: 0
B23: Costo financiero | C23: 0
B24: Utilidad antes de ISR | C24: =C21-C22-C23 -> 0
B25: ISR | C25: =C24*Tabla2[[#This Row],[% del costo]] -> 0 | D25: =_xlfn.IFS(C24<=D34,C34,C24<=D35,C35,C24>D36,C36) -> 0.1
B26: Utilidad neta | C26: =C24-C25 -> 0 | D26: =IFERROR(Tabla2[[#This Row],[Costo]]/F12,"")
B29: Utilidad Neta del Ejercicio | C29: =C26 -> 0 | D29: =IFERROR(+C29/F12,"")
A32: Hasta | B32: IMPUESTO SOBRE LA RENTA COSTA RICA
A33: Hasta | B33: Ingresos brutos | C33: Tarifa(Se aplica sobre renta neta total) | D33: Ingresos Brutos $
A34: Mayor de | B34: 54303000 | C34: 0.1 | D34: =B34/565 -> 96111.504
B35: 109228000 | C35: 0.2 | D35: =B35/565 -> 193323.89 | F35: =_xlfn.IFS(C14<=D34,C34,C14<=D35,C35,C14>D36,C36) -> 0.1
B36: 109228000 | C36: 0.3 | D36: =B36/565 -> 193323.89

Sheet Resumen para oferta
B1: Ítem | C1: Descripción | D1: Cant. | E1: Precio Venta | F1: Total
B2: 1 | C2: HARDWARE | D2: 1 | F2: =E2*D2 -> 0
B3: 2 | C3: MATERIALES DE INSTALACION Y REDES | D3: 1 | E3: 0 | F3: =E3*D3 -> 0
B4: 3 | C4: Centro de Datos/Monitoreo | D4: 1 | E4: 0 | F4: =E4*D4 -> 0
B5: 5 | C5: GASTOS DE VIAJE Y ESTADIAS | D5: 1 | E5: 0 | F5: =E5*D5 -> 0
B6: 6 | C6: ADMINISTRACION DE PROYECTO | D6: 1 | E6: 0 | F6: =E6*D6 -> 0
E7: Sub Total | F7: =SUM(F2:F6) -> 0
B8: 4 | C8: SERVICIOS DE IMPLEMENTACION | D8: 1 | E8: 0 | F8: =E8*D8 -> 0
E9: IVA | F9: =F7*0.13 -> 0
E10: Total | F10: =SUM(F7:F9) -> 0
B15: Ítem | C15: Cantidad | D15: Proveedor | E15: #Parte | F15: Marca | G15: Marca | H15: Descripción / Código | J15: Costo Unitario | K15: Sub Total
B17: 1 | K17: =+J17*C17 -> 0
B18: 2 | C18: =+Equipos!D6 -> 0 | H18: =+Equipos!B6 -> 0 | J18: =+Equipos!O6 -> 0 | K18: =+J18*C18 -> 0
B19: 3 | C19: =+Equipos!D7 -> 0 | H19: =+Equipos!B7 -> 0 | J19: =+Equipos!O7 -> 0 | K19: =+J19*C19 -> 0
B20: 4 | K20: =+J20*C20 -> 0
B21: 5 | K21: =J21*C21 -> 0
B22: 6 | K22: =J22*C22 -> 0
B23: 7 | C23: =+'Productos 5'!C9 -> 0 | J23: =+'Productos 5'!N9 -> 0 | K23: =J23*C23 -> 0
B24: 6 | C24: =+'Productos 5'!C10 -> 0 | J24: =+'Productos 5'!N10 -> 0 | K24: =J24*C24 -> 0
B25: 7 | C25: =+'Productos 5'!C11 -> 0 | J25: =+'Productos 5'!N11 -> 0 | K25: =J25*C25 -> 0
B26: Precios ya incluyen impuesto de venta
J27: Subtotal | K27: =SUM(K17:K25) -> 0
J28: Materiales y accesorios | K28: =+MATERIALES!O46 -> 0
J29: Mano de obra por instalación y puesta en marcha | K29: =+'OPEX GV'!O17 -> 0
J30: Impuesto de Ventas | K30: =(K27+K28+K29)*0.13 -> 0
J31: Total de Oferta | K31: =SUM(K27:K30) -> 0
K39: =K31*635 -> 0
B44: Ítem | C44: Cantidad | F44: IMG | G44: Marca | H44: Descripción / Código | J44: Costo Unitario | K44: Sub Total
B45: Implementación de sistemas de seguridad
B46: 1 | C46: 1 | G46: GV | H46: ='Productos 2'!A6 -> 0 | J46: ='Productos 2'!N6 -> 0 | K46: =+J46*C46 -> 0
B47: Precios ya incluyen impuesto de venta
J48: Subtotal | K48: =K46 -> 0
J49: Materiales y accesorios | K49: =+MATERIALES!O83 -> 0
J50: Mano de obra por instalación y puesta en marcha | K50: 0
J51: Impuesto de Ventas | K51: =(K48+K49+K50)*0.13 -> 0
J52: Total de Oferta | K52: =SUM(K48:K51) -> 0

Sheet COTIZACIÓN 
B5: Cédula Jurídica: 3101666618 | I5: www.grupovision.org
B6: Tibas Anselmo Llorente, Cámara Costarricense de la Construción
B7: San José, Costa Rica
B8: Teléfonos: (506) 40101090
J10: V1
B12: Nombre: | I12: Fecha: | J12: =TODAY() -> 46314
B13: Atención: | I13: Cotización #: | J13: T5-0000000-26
B14: Correo: | I14: Validez de: | J14: 15 días
B15: Tel: | I15: Método de envío: | J15: Electrónico
B16: Dirreción: | C16: San José, Costa Rica | I16: Ref:
B17: Asesor:
B20: Cantidad | C20: Descripción | I20: Precio U. | J20: Total Contado
C21: Equipos
B22: =Equipos!D6 -> 0 | C22: =Equipos!B6 -> 0 | I22: =Equipos!O6 -> 0 | J22: =I22*B22 -> 0
B23: =Equipos!D7 -> 0 | C23: =Equipos!B7 -> 0 | I23: =Equipos!O7 -> 0 | J23: =I23*B23 -> 0
B24: =Equipos!D8 -> 0 | C24: =Equipos!B8 -> 0 | I24: =Equipos!O8 -> 0 | J24: =I24*B24 -> 0
B25: =Equipos!D9 -> 0 | C25: =Equipos!B9 -> 0 | I25: =Equipos!O9 -> 0 | J25: =I25*B25 -> 0
B26: =Equipos!D10 -> 0 | C26: =Equipos!B10 -> 0 | I26: =Equipos!O10 -> 0 | J26: =I26*B26 -> 0
B27: =Equipos!D11 -> 0 | C27: =Equipos!B11 -> 0 | I27: =Equipos!O11 -> 0 | J27: =I27*B27 -> 0
B28: =Equipos!D12 -> 0 | C28: =Equipos!B12 -> 0 | I28: =Equipos!O12 -> 0 | J28: =I28*B28 -> 0
B29: =Equipos!D13 -> 0 | C29: =Equipos!B13 -> 0 | I29: =Equipos!O13 -> 0 | J29: =I29*B29 -> 0
B30: =Equipos!D14 -> 0 | C30: =Equipos!B14 -> 0 | I30: =Equipos!O14 -> 0 | J30: =I30*B30 -> 0
B31: =Equipos!D15 -> 0 | C31: =Equipos!B15 -> 0 | I31: =Equipos!O15 -> 0 | J31: =I31*B31 -> 0
B32: =Equipos!D16 -> 0 | C32: =Equipos!B16 -> 0 | I32: =Equipos!O16 -> 0 | J32: =I32*B32 -> 0
B33: =Equipos!D17 -> 0 | C33: =Equipos!B17 -> 0 | I33: =Equipos!O17 -> 0 | J33: =I33*B33 -> 0
... B71: =Equipos!D55 -> 0 | C71: =Equipos!B55 -> 0 | I71: =Equipos!O55 -> 0 | J71: =I71*B71 -> 0
B72: ****************************************U.L****************************************
I74: SUBTOTAL | J74: =SUM(J21:J73) -> 0 | K74: =+Equipos!P57+'OPEX GV'!O17 -> 0 | L74: =IF(ROUND(SUM(J22:J71)-SUBTOTAL(109,J22:J71),2)<>0,"OJO: hay l"&_xlfn.UNICHAR(237)&"neas ocultas con monto. Mostralas: si no, suman pero no aparecen en la cotizaci"&_xlfn.UNICHAR(243)&"n.","")
I75: IMPUESTO | J75: =J74*IF(LOWER(TRIM('Datos del proyecto'!$B$15))="si",0,IF(ISNUMBER('Datos del proyecto'!$B$16),IF('Datos del proyecto'!$B$16>1,'Datos del proyecto'!$B$16/100,'Datos del proyecto'!$B$16),0.13)) -> 0
B76: ss | I76: TOTAL | J76: =ROUNDDOWN(J74+J75,2) -> 0
B88: [Nombre del asesor responsable]
B89: Depto Preventa y Diseño
B90: Edificio Cámara Costarricense de la Construcción Piso 4, oficina 401
B91: Teléfonos: (506) 40101090
B92: E-mail: [correo del asesor]

Sheet COTIZACION (Financ)
B5: Cédula Jurídica: 3101666618 | I5: www.grupovision.org
B6: Tibas Anselmo Llorente, Cámara Costarricense de la Construción
B7: San José, Costa Rica
B8: Teléfonos: (506) 40101090
J10: V1
B12: Nombre: | I12: Fecha: | J12: =TODAY() -> 46314
B13: Atención: | I13: Cotización #: | J13: T5-0000000-26
B14: Correo: | I14: Validez de: | J14: 15 días
B15: Tel: | I15: Método de envío: | J15: Electrónico
B16: Dirreción: | C16: San José, Costa Rica | I16: Ref:
B17: Asesor:
B20: Cantidad | C20: Descripción | I20: Precio Unitario Mensual | J20: Total Mensual
C21: Equipos
B22: =Equipos!D6 -> 0 | C22: =Equipos!B6 -> 0 | I22: =IFERROR(IF(Equipos!Q6="","",INDEX(Financiamiento!$C:$C,12+(Equipos!Q6-1)*17)),"") | J22: =IFERROR(I22*B22,"")
B23: =Equipos!D7 -> 0 | C23: =Equipos!B7 -> 0 | I23: =IFERROR(IF(Equipos!Q7="","",INDEX(Financiamiento!$C:$C,12+(Equipos!Q7-1)*17)),"") | J23: =IFERROR(I23*B23,"")
B24: =Equipos!D8 -> 0 | C24: =Equipos!B8 -> 0 | I24: =IFERROR(IF(Equipos!Q8="","",INDEX(Financiamiento!$C:$C,12+(Equipos!Q8-1)*17)),"") | J24: =IFERROR(I24*B24,"")
B25: =Equipos!D9 -> 0 | C25: =Equipos!B9 -> 0 | I25: =IFERROR(IF(Equipos!Q9="","",INDEX(Financiamiento!$C:$C,12+(Equipos!Q9-1)*17)),"") | J25: =IFERROR(I25*B25,"")
B26: =Equipos!D10 -> 0 | C26: =Equipos!B10 -> 0 | I26: =IFERROR(IF(Equipos!Q10="","",INDEX(Financiamiento!$C:$C,12+(Equipos!Q10-1)*17)),"") | J26: =IFERROR(I26*B26,"")
B27: =Equipos!D11 -> 0 | C27: =Equipos!B11 -> 0 | I27: =IFERROR(IF(Equipos!Q11="","",INDEX(Financiamiento!$C:$C,12+(Equipos!Q11-1)*17)),"") | J27: =IFERROR(I27*B27,"")
B28: =Equipos!D12 -> 0 | C28: =Equipos!B12 -> 0 | I28: =IFERROR(IF(Equipos!Q12="","",INDEX(Financiamiento!$C:$C,12+(Equipos!Q12-1)*17)),"") | J28: =IFERROR(I28*B28,"")
B29: =Equipos!D13 -> 0 | C29: =Equipos!B13 -> 0 | I29: =IFERROR(IF(Equipos!Q13="","",INDEX(Financiamiento!$C:$C,12+(Equipos!Q13-1)*17)),"") | J29: =IFERROR(I29*B29,"")
B30: =Equipos!D14 -> 0 | C30: =Equipos!B14 -> 0 | I30: =IFERROR(IF(Equipos!Q14="","",INDEX(Financiamiento!$C:$C,12+(Equipos!Q14-1)*17)),"") | J30: =IFERROR(I30*B30,"")
B31: =Equipos!D15 -> 0 | C31: =Equipos!B15 -> 0 | I31: =IFERROR(IF(Equipos!Q15="","",INDEX(Financiamiento!$C:$C,12+(Equipos!Q15-1)*17)),"") | J31: =IFERROR(I31*B31,"")
B32: =Equipos!D16 -> 0 | C32: =Equipos!B16 -> 0 | I32: =IFERROR(IF(Equipos!Q16="","",INDEX(Financiamiento!$C:$C,12+(Equipos!Q16-1)*17)),"") | J32: =IFERROR(I32*B32,"")
B33: =Equipos!D17 -> 0 | C33: =Equipos!B17 -> 0 | I33: =IFERROR(IF(Equipos!Q17="","",INDEX(Financiamiento!$C:$C,12+(Equipos!Q17-1)*17)),"") | J33: =IFERROR(I33*B33,"")
... B71: =Equipos!D55 -> 0 | C71: =Equipos!B55 -> 0 | I71: =IFERROR(IF(Equipos!Q55="","",INDEX(Financiamiento!$C:$C,12+(Equipos!Q55-1)*17)),"") | J71: =IFERROR(I71*B71,"")
B72: ****************************************U.L****************************************
I74: SUBTOTAL | J74: =SUM(J21:J73) -> 0 | K74: =+Equipos!P57+'OPEX GV'!O17 -> 0 | L74: =IF(ROUND(SUM(J22:J71)-SUBTOTAL(109,J22:J71),2)<>0,"OJO: hay l"&_xlfn.UNICHAR(237)&"neas ocultas con monto. Mostralas: si no, suman pero no aparecen en la cotizaci"&_xlfn.UNICHAR(243)&"n.","")
I75: IMPUESTO | J75: =J74*IF(LOWER(TRIM('Datos del proyecto'!$B$15))="si",0,IF(ISNUMBER('Datos del proyecto'!$B$16),IF('Datos del proyecto'!$B$16>1,'Datos del proyecto'!$B$16/100,'Datos del proyecto'!$B$16),0.13)) -> 0
B76: ss | I76: TOTAL MENSUAL | J76: =ROUNDDOWN(J74+J75,2) -> 0
B88: [Nombre del asesor responsable]
B89: Depto Preventa y Diseño
B90: Edificio Cámara Costarricense de la Construcción Piso 4, oficina 401
B91: Teléfonos: (506) 40101090
B92: E-mail: [correo del asesor]

Sheet Equipos
B1: MATRIZ DE COSTO PROYECTO:
L2: 0.04
B3: Productos 1 | G3: Transporte | H3: Imprevistos | I3: IVA | J3: DAI | K3: Costo Untit | L3: Administración | M3: Costo total | N3: Margen GV | O3: Precio Venta | P3: Precio Venta | Q3: Financ.
B4: Description | C4: IMPORTADO | D4: Qty | E4: Costo Unit | F4: Costo Total | G4: 0.1 | H4: 0.03 | I4: 0 | J4: 0.15 | K4: Nacionalizado | L4: 0.03 | M4: Nacionalizado | N4: 0.274 | O4: Unitario | P4: Total
B5: Sección 1
C6: no | D6: 0 | E6: 0 | F6: =E6*D6 -> 0 | G6: =IF(C6="si",E6*$G$4,0) -> 0 | H6: =(E6+G6)*$H$4 -> 0 | I6: =+(E6+G6+H6)*$I$4 -> 0 | J6: =IF(C6="si",(E6+G6+H6+I6)*$J$4,0) -> 0 | K6: =E6+G6+H6+I6+J6 -> 0 | L6: =K6*$L$4 -> 0 | M6: =(K6+L6)*D6 -> 0 | N6: =(K6+L6)*$N$4/(1-$N$4) -> 0 | O6: =N6+K6+L6 -> 0 | P6: =O6*D6 -> 0
C7: no | D7: 0 | E7: 0 | F7: =E7*D7 -> 0 | G7: =IF(C7="si",E7*$G$4,0) -> 0 | H7: =(E7+G7)*$H$4 -> 0 | I7: =+(E7+G7+H7)*$I$4 -> 0 | J7: =IF(C7="si",(E7+G7+H7+I7)*$J$4,0) -> 0 | K7: =E7+G7+H7+I7+J7 -> 0 | L7: =K7*$L$4 -> 0 | M7: =(K7+L7)*D7 -> 0 | N7: =(K7+L7)*$N$4/(1-$N$4) -> 0 | O7: =N7+K7+L7 -> 0 | P7: =O7*D7 -> 0
C8: no | D8: 0 | E8: 0 | F8: =E8*D8 -> 0 | G8: =IF(C8="si",E8*$G$4,0) -> 0 | H8: =(E8+G8)*$H$4 -> 0 | I8: =+(E8+G8+H8)*$I$4 -> 0 | J8: =IF(C8="si",(E8+G8+H8+I8)*$J$4,0) -> 0 | K8: =E8+G8+H8+I8+J8 -> 0 | L8: =K8*$L$4 -> 0 | M8: =(K8+L8)*D8 -> 0 | N8: =(K8+L8)*$N$4/(1-$N$4) -> 0 | O8: =N8+K8+L8 -> 0 | P8: =O8*D8 -> 0
C9: no | D9: 0 | E9: 0 | F9: =E9*D9 -> 0 | G9: =IF(C9="si",E9*$G$4,0) -> 0 | H9: =(E9+G9)*$H$4 -> 0 | I9: =+(E9+G9+H9)*$I$4 -> 0 | J9: =IF(C9="si",(E9+G9+H9+I9)*$J$4,0) -> 0 | K9: =E9+G9+H9+I9+J9 -> 0 | L9: =K9*$L$4 -> 0 | M9: =(K9+L9)*D9 -> 0 | N9: =(K9+L9)*$N$4/(1-$N$4) -> 0 | O9: =N9+K9+L9 -> 0 | P9: =O9*D9 -> 0
C10: no | D10: 0 | E10: 0 | F10: =E10*D10 -> 0 | G10: =IF(C10="si",E10*$G$4,0) -> 0 | H10: =(E10+G10)*$H$4 -> 0 | I10: =+(E10+G10+H10)*$I$4 -> 0 | J10: =IF(C10="si",(E10+G10+H10+I10)*$J$4,0) -> 0 | K10: =E10+G10+H10+I10+J10 -> 0 | L10: =K10*$L$4 -> 0 | M10: =(K10+L10)*D10 -> 0 | N10: =(K10+L10)*$N$4/(1-$N$4) -> 0 | O10: =N10+K10+L10 -> 0 | P10: =O10*D10 -> 0
C11: no | D11: 0 | E11: 0 | F11: =E11*D11 -> 0 | G11: =IF(C11="si",E11*$G$4,0) -> 0 | H11: =(E11+G11)*$H$4 -> 0 | I11: =+(E11+G11+H11)*$I$4 -> 0 | J11: =IF(C11="si",(E11+G11+H11+I11)*$J$4,0) -> 0 | K11: =E11+G11+H11+I11+J11 -> 0 | L11: =K11*$L$4 -> 0 | M11: =(K11+L11)*D11 -> 0 | N11: =(K11+L11)*$N$4/(1-$N$4) -> 0 | O11: =N11+K11+L11 -> 0 | P11: =O11*D11 -> 0
C12: no | D12: 0 | E12: 0 | F12: =E12*D12 -> 0 | G12: =IF(C12="si",E12*$G$4,0) -> 0 | H12: =(E12+G12)*$H$4 -> 0 | I12: =+(E12+G12+H12)*$I$4 -> 0 | J12: =IF(C12="si",(E12+G12+H12+I12)*$J$4,0) -> 0 | K12: =E12+G12+H12+I12+J12 -> 0 | L12: =K12*$L$4 -> 0 | M12: =(K12+L12)*D12 -> 0 | N12: =(K12+L12)*$N$4/(1-$N$4) -> 0 | O12: =N12+K12+L12 -> 0 | P12: =O12*D12 -> 0
C13: no | D13: 0 | E13: 0 | F13: =E13*D13 -> 0 | G13: =IF(C13="si",E13*$G$4,0) -> 0 | H13: =(E13+G13)*$H$4 -> 0 | I13: =+(E13+G13+H13)*$I$4 -> 0 | J13: =IF(C13="si",(E13+G13+H13+I13)*$J$4,0) -> 0 | K13: =E13+G13+H13+I13+J13 -> 0 | L13: =K13*$L$4 -> 0 | M13: =(K13+L13)*D13 -> 0 | N13: =(K13+L13)*$N$4/(1-$N$4) -> 0 | O13: =N13+K13+L13 -> 0 | P13: =O13*D13 -> 0
C14: no | D14: 0 | E14: 0 | F14: =E14*D14 -> 0 | G14: =IF(C14="si",E14*$G$4,0) -> 0 | H14: =(E14+G14)*$H$4 -> 0 | I14: =+(E14+G14+H14)*$I$4 -> 0 | J14: =IF(C14="si",(E14+G14+H14+I14)*$J$4,0) -> 0 | K14: =E14+G14+H14+I14+J14 -> 0 | L14: =K14*$L$4 -> 0 | M14: =(K14+L14)*D14 -> 0 | N14: =(K14+L14)*$N$4/(1-$N$4) -> 0 | O14: =N14+K14+L14 -> 0 | P14: =O14*D14 -> 0
C15: no | D15: 0 | E15: 0 | F15: =E15*D15 -> 0 | G15: =IF(C15="si",E15*$G$4,0) -> 0 | H15: =(E15+G15)*$H$4 -> 0 | I15: =+(E15+G15+H15)*$I$4 -> 0 | J15: =IF(C15="si",(E15+G15+H15+I15)*$J$4,0) -> 0 | K15: =E15+G15+H15+I15+J15 -> 0 | L15: =K15*$L$4 -> 0 | M15: =(K15+L15)*D15 -> 0 | N15: =(K15+L15)*$N$4/(1-$N$4) -> 0 | O15: =N15+K15+L15 -> 0 | P15: =O15*D15 -> 0
C16: no | D16: 0 | E16: 0 | F16: =E16*D16 -> 0 | G16: =IF(C16="si",E16*$G$4,0) -> 0 | H16: =(E16+G16)*$H$4 -> 0 | I16: =+(E16+G16+H16)*$I$4 -> 0 | J16: =IF(C16="si",(E16+G16+H16+I16)*$J$4,0) -> 0 | K16: =E16+G16+H16+I16+J16 -> 0 | L16: =K16*$L$4 -> 0 | M16: =(K16+L16)*D16 -> 0 | N16: =(K16+L16)*$N$4/(1-$N$4) -> 0 | O16: =N16+K16+L16 -> 0 | P16: =O16*D16 -> 0
C17: no | D17: 0 | E17: 0 | F17: =E17*D17 -> 0 | G17: =IF(C17="si",E17*$G$4,0) -> 0 | H17: =(E17+G17)*$H$4 -> 0 | I17: =+(E17+G17+H17)*$I$4 -> 0 | J17: =IF(C17="si",(E17+G17+H17+I17)*$J$4,0) -> 0 | K17: =E17+G17+H17+I17+J17 -> 0 | L17: =K17*$L$4 -> 0 | M17: =(K17+L17)*D17 -> 0 | N17: =(K17+L17)*$N$4/(1-$N$4) -> 0 | O17: =N17+K17+L17 -> 0 | P17: =O17*D17 -> 0
... C55: no | D55: 0 | E55: 0 | F55: =E55*D55 -> 0 | G55: =IF(C55="si",E55*$G$4,0) -> 0 | H55: =(E55+G55)*$H$4 -> 0 | I55: =+(E55+G55+H55)*$I$4 -> 0 | J55: =IF(C55="si",(E55+G55+H55+I55)*$J$4,0) -> 0 | K55: =E55+G55+H55+I55+J55 -> 0 | L55: =K55*$L$4 -> 0 | M55: =(K55+L55)*D55 -> 0 | N55: =(K55+L55)*$N$4/(1-$N$4) -> 0 | O55: =N55+K55+L55 -> 0 | P55: =O55*D55 -> 0
E57: Total FOB | F57: =SUM(F3:F55) -> 0 | K57: Costo Nac. | M57: =SUM(M6:M55) -> 0 | O57: Total Venta | P57: =SUM(P6:P55) -> 0
O58: UTILIDAD | P58: =P57-M57 -> 0
B60: IMPORTADO
B61: si
B62: no

Sheet Productos 2
A1: MATRIZ DE COSTO PROYECTO: | E1: =+Equipos!E1 -> 0
A3: Productos 2 | F3: Transporte | G3: Seguros | H3: IVA | I3: DAI | J3: Costo Untit | K3: Administración | L3: Costo total | M3: Margen GV | N3: Precio Venta | O3: Precio Venta | P3: Financ.
A4: Description | C4: Qty | D4: Costo Unit | E4: Costo Total | F4: 0.1 | G4: 0 | H4: 0.13 | I4: 0.14 | J4: Nacionalizado | K4: 0.03 | L4: Nacionaliado | M4: 0.3 | N4: Unitario | O4: Total
A5: Sección 1 | B5: IMPORTADO
B6: no | C6: 0 | D6: 0 | E6: =+D6*C6 -> 0 | F6: =IF(B6="si",D6*$F$4,0) -> 0 | G6: 0 | H6: =(D6+F6+G6)*$H$4 -> 0 | I6: =IF(B6="si",(D6+F6+G6+H6)*$I$4,0) -> 0 | J6: =D6+F6+G6+H6+I6 -> 0 | K6: =J6*$K$4 -> 0 | L6: =(J6+K6)*C6 -> 0 | M6: =(J6+K6)*$M$4/(1-$M$4) -> 0 | N6: =M6+J6+K6 -> 0 | O6: =N6*C6 -> 0
B7: no | C7: 0 | D7: 0 | E7: =+D7*C7 -> 0 | F7: =IF(B7="si",D7*$F$4,0) -> 0 | G7: =(D7+F7)*$G$4 -> 0 | H7: =(D7+F7+G7)*$H$4 -> 0 | I7: =IF(B7="si",(D7+F7+G7+H7)*$I$4,0) -> 0 | J7: =D7+F7+G7+H7+I7 -> 0 | K7: =J7*$K$4 -> 0 | L7: =(J7+K7)*C7 -> 0 | M7: =(J7+K7)*$M$4/(1-$M$4) -> 0 | N7: =M7+J7+K7 -> 0 | O7: =N7*C7 -> 0
B8: no | C8: 0 | D8: 0 | E8: =+D8*C8 -> 0 | F8: =IF(B8="si",D8*$F$4,0) -> 0 | G8: =(D8+F8)*$G$4 -> 0 | H8: =(D8+F8+G8)*$H$4 -> 0 | I8: =IF(B8="si",(D8+F8+G8+H8)*$I$4,0) -> 0 | J8: =D8+F8+G8+H8+I8 -> 0 | K8: =J8*$K$4 -> 0 | L8: =(J8+K8)*C8 -> 0 | M8: =(J8+K8)*$M$4/(1-$M$4) -> 0 | N8: =M8+J8+K8 -> 0 | O8: =N8*C8 -> 0
B9: no | C9: 0 | D9: 0 | E9: =+D9*C9 -> 0 | F9: =IF(B9="si",D9*$F$4,0) -> 0 | G9: =(D9+F9)*$G$4 -> 0 | H9: =(D9+F9+G9)*$H$4 -> 0 | I9: =IF(B9="si",(D9+F9+G9+H9)*$I$4,0) -> 0 | J9: =D9+F9+G9+H9+I9 -> 0 | K9: =J9*$K$4 -> 0 | L9: =(J9+K9)*C9 -> 0 | M9: =(J9+K9)*$M$4/(1-$M$4) -> 0 | N9: =M9+J9+K9 -> 0 | O9: =N9*C9 -> 0
B10: no | C10: 0 | D10: 0 | E10: =+D10*C10 -> 0 | F10: =IF(B10="si",D10*$F$4,0) -> 0 | G10: =(D10+F10)*$G$4 -> 0 | H10: =(D10+F10+G10)*$H$4 -> 0 | I10: =IF(B10="si",(D10+F10+G10+H10)*$I$4,0) -> 0 | J10: =D10+F10+G10+H10+I10 -> 0 | K10: =J10*$K$4 -> 0 | L10: =(J10+K10)*C10 -> 0 | M10: =(J10+K10)*$M$4/(1-$M$4) -> 0 | N10: =M10+J10+K10 -> 0 | O10: =N10*C10 -> 0
B11: no | C11: 0 | D11: 0 | E11: =+D11*C11 -> 0 | F11: =IF(B11="si",D11*$F$4,0) -> 0 | G11: =(D11+F11)*$G$4 -> 0 | H11: =(D11+F11+G11)*$H$4 -> 0 | I11: =IF(B11="si",(D11+F11+G11+H11)*$I$4,0) -> 0 | J11: =D11+F11+G11+H11+I11 -> 0 | K11: =J11*$K$4 -> 0 | L11: =(J11+K11)*C11 -> 0 | M11: =(J11+K11)*$M$4/(1-$M$4) -> 0 | N11: =M11+J11+K11 -> 0 | O11: =N11*C11 -> 0
B12: no | C12: 0 | D12: 0 | E12: =+D12*C12 -> 0 | F12: =IF(B12="si",D12*$F$4,0) -> 0 | G12: =(D12+F12)*$G$4 -> 0 | H12: =(D12+F12+G12)*$H$4 -> 0 | I12: =IF(B12="si",(D12+F12+G12+H12)*$I$4,0) -> 0 | J12: =D12+F12+G12+H12+I12 -> 0 | K12: =J12*$K$4 -> 0 | L12: =(J12+K12)*C12 -> 0 | M12: =(J12+K12)*$M$4/(1-$M$4) -> 0 | N12: =M12+J12+K12 -> 0 | O12: =N12*C12 -> 0
B13: no | C13: 0 | D13: 0 | E13: =+D13*C13 -> 0 | F13: =IF(B13="si",D13*$F$4,0) -> 0 | G13: =(D13+F13)*$G$4 -> 0 | H13: =(D13+F13+G13)*$H$4 -> 0 | I13: =IF(B13="si",(D13+F13+G13+H13)*$I$4,0) -> 0 | J13: =D13+F13+G13+H13+I13 -> 0 | K13: =J13*$K$4 -> 0 | L13: =(J13+K13)*C13 -> 0 | M13: =(J13+K13)*$M$4/(1-$M$4) -> 0 | N13: =M13+J13+K13 -> 0 | O13: =N13*C13 -> 0
B14: no | C14: 0 | D14: 0 | E14: =+D14*C14 -> 0 | F14: =IF(B14="si",D14*$F$4,0) -> 0 | G14: =(D14+F14)*$G$4 -> 0 | H14: =(D14+F14+G14)*$H$4 -> 0 | I14: =IF(B14="si",(D14+F14+G14+H14)*$I$4,0) -> 0 | J14: =D14+F14+G14+H14+I14 -> 0 | K14: =J14*$K$4 -> 0 | L14: =(J14+K14)*C14 -> 0 | M14: =(J14+K14)*$M$4/(1-$M$4) -> 0 | N14: =M14+J14+K14 -> 0 | O14: =N14*C14 -> 0
B15: no | C15: 0 | D15: 0 | E15: =+D15*C15 -> 0 | F15: =IF(B15="si",D15*$F$4,0) -> 0 | G15: =(D15+F15)*$G$4 -> 0 | H15: =(D15+F15+G15)*$H$4 -> 0 | I15: =IF(B15="si",(D15+F15+G15+H15)*$I$4,0) -> 0 | J15: =D15+F15+G15+H15+I15 -> 0 | K15: =J15*$K$4 -> 0 | L15: =(J15+K15)*C15 -> 0 | M15: =(J15+K15)*$M$4/(1-$M$4) -> 0 | N15: =M15+J15+K15 -> 0 | O15: =N15*C15 -> 0
D17: Total FOB | E17: =SUM(E6:E15) -> 0 | J17: Costo Nac. | L17: =SUM(L6:L15) -> 0 | N17: Total Venta | O17: =SUM(O6:O15) -> 0
N18: UTILIDAD | O18: =O17-L17 -> 0
A20: IMPORTADO
A21: si
A22: no

Sheet Productos 3
A1: MATRIZ DE COSTO PROYECTO: | E1: =+Equipos!E1 -> 0
A3: Productos 3 | F3: Transporte | G3: Seguros | H3: IVA | I3: DAI | J3: Costo Untit | K3: Administración | L3: Costo total | M3: Margen GV | N3: Precio Venta | O3: Precio Venta
A4: Description | C4: Qty | D4: Costo Unit | E4: Costo Total | F4: 0.1 | G4: 0 | H4: 0.13 | I4: 0.14 | J4: Nacionalizado | K4: 0.03 | L4: Nacionaliado | M4: 0.3 | N4: Unitario | O4: Total
A5: Licencias | B5: IMPORTADO
B6: no | C6: 0 | D6: 0 | E6: =+D6*C6 -> 0 | F6: =IF(B6="si",D6*$F$4,0) -> 0 | G6: 0 | H6: =(D6+F6+G6)*$H$4 -> 0 | I6: =IF(B6="si",(D6+F6+G6+H6)*$I$4,0) -> 0 | J6: =D6+F6+G6+H6+I6 -> 0 | K6: =J6*$K$4 -> 0 | L6: =(J6+K6)*C6 -> 0 | M6: =(J6+K6)*$M$4/(1-$M$4) -> 0 | N6: =M6+J6+K6 -> 0 | O6: =N6*C6 -> 0
B7: no | C7: 0 | D7: 0 | E7: =+D7*C7 -> 0 | F7: =IF(B7="si",D7*$F$4,0) -> 0 | G7: =(D7+F7)*$G$4 -> 0 | H7: =(D7+F7+G7)*$H$4 -> 0 | I7: =IF(B7="si",(D7+F7+G7+H7)*$I$4,0) -> 0 | J7: =D7+F7+G7+H7+I7 -> 0 | K7: =J7*$K$4 -> 0 | L7: =(J7+K7)*C7 -> 0 | M7: =(J7+K7)*$M$4/(1-$M$4) -> 0 | N7: =M7+J7+K7 -> 0 | O7: =N7*C7 -> 0
B8: no | C8: 0 | D8: 0 | E8: =+D8*C8 -> 0 | F8: =IF(B8="si",D8*$F$4,0) -> 0 | G8: =(D8+F8)*$G$4 -> 0 | H8: =(D8+F8+G8)*$H$4 -> 0 | I8: =IF(B8="si",(D8+F8+G8+H8)*$I$4,0) -> 0 | J8: =D8+F8+G8+H8+I8 -> 0 | K8: =J8*$K$4 -> 0 | L8: =(J8+K8)*C8 -> 0 | M8: =(J8+K8)*$M$4/(1-$M$4) -> 0 | N8: =M8+J8+K8 -> 0 | O8: =N8*C8 -> 0
B9: no | C9: 0 | D9: 0 | E9: =+D9*C9 -> 0 | F9: =IF(B9="si",D9*$F$4,0) -> 0 | G9: =(D9+F9)*$G$4 -> 0 | H9: =(D9+F9+G9)*$H$4 -> 0 | I9: =IF(B9="si",(D9+F9+G9+H9)*$I$4,0) -> 0 | J9: =D9+F9+G9+H9+I9 -> 0 | K9: =J9*$K$4 -> 0 | L9: =(J9+K9)*C9 -> 0 | M9: =(J9+K9)*$M$4/(1-$M$4) -> 0 | N9: =M9+J9+K9 -> 0 | O9: =N9*C9 -> 0
B10: no | C10: 0 | D10: 0 | E10: =+D10*C10 -> 0 | F10: =IF(B10="si",D10*$F$4,0) -> 0 | G10: =(D10+F10)*$G$4 -> 0 | H10: =(D10+F10+G10)*$H$4 -> 0 | I10: =IF(B10="si",(D10+F10+G10+H10)*$I$4,0) -> 0 | J10: =D10+F10+G10+H10+I10 -> 0 | K10: =J10*$K$4 -> 0 | L10: =(J10+K10)*C10 -> 0 | M10: =(J10+K10)*$M$4/(1-$M$4) -> 0 | N10: =M10+J10+K10 -> 0 | O10: =N10*C10 -> 0
B11: no | C11: 0 | D11: 0 | E11: =+D11*C11 -> 0 | F11: =IF(B11="si",D11*$F$4,0) -> 0 | G11: =(D11+F11)*$G$4 -> 0 | H11: =(D11+F11+G11)*$H$4 -> 0 | I11: =IF(B11="si",(D11+F11+G11+H11)*$I$4,0) -> 0 | J11: =D11+F11+G11+H11+I11 -> 0 | K11: =J11*$K$4 -> 0 | L11: =(J11+K11)*C11 -> 0 | M11: =(J11+K11)*$M$4/(1-$M$4) -> 0 | N11: =M11+J11+K11 -> 0 | O11: =N11*C11 -> 0
B12: no | C12: 0 | D12: 0 | E12: =+D12*C12 -> 0 | F12: =IF(B12="si",D12*$F$4,0) -> 0 | G12: =(D12+F12)*$G$4 -> 0 | H12: =(D12+F12+G12)*$H$4 -> 0 | I12: =IF(B12="si",(D12+F12+G12+H12)*$I$4,0) -> 0 | J12: =D12+F12+G12+H12+I12 -> 0 | K12: =J12*$K$4 -> 0 | L12: =(J12+K12)*C12 -> 0 | M12: =(J12+K12)*$M$4/(1-$M$4) -> 0 | N12: =M12+J12+K12 -> 0 | O12: =N12*C12 -> 0
A13: Servidores
B14: no | C14: 0 | D14: 0 | E14: =+C14*D14*(1-C23) -> 0 | F14: =IF(B14="si",D14*$F$4,0) -> 0 | G14: =(D14+F14)*$G$4 -> 0 | H14: =(D14+F14+G14)*$H$4 -> 0 | I14: =IF(B14="si",(D14+F14+G14+H14)*$I$4,0) -> 0 | J14: =D14+F14+G14+H14+I14 -> 0 | K14: =J14*$K$4 -> 0 | L14: =(J14+K14)*C14 -> 0 | M14: =(J14+K14)*$M$4/(1-$M$4) -> 0 | N14: =M14+J14+K14 -> 0 | O14: =N14*C14 -> 0
B15: no | C15: 0 | D15: 0 | E15: =+C15*D15 -> 0 | F15: =IF(B15="si",D15*$F$4,0) -> 0 | G15: =(D15+F15)*$G$4 -> 0 | H15: =(D15+F15+G15)*$H$4 -> 0 | I15: =IF(B15="si",(D15+F15+G15+H15)*$I$4,0) -> 0 | J15: =D15+F15+G15+H15+I15 -> 0 | K15: =J15*$K$4 -> 0 | L15: =(J15+K15)*C15 -> 0 | M15: =(J15+K15)*$M$4/(1-$M$4) -> 0 | N15: =M15+J15+K15 -> 0 | O15: =N15*C15 -> 0
B16: no | C16: 0 | D16: 0 | E16: =+C16*D16 -> 0 | F16: =IF(B16="si",D16*$F$4,0) -> 0 | G16: =(D16+F16)*$G$4 -> 0 | H16: =(D16+F16+G16)*$H$4 -> 0 | I16: =IF(B16="si",(D16+F16+G16+H16)*$I$4,0) -> 0 | J16: =D16+F16+G16+H16+I16 -> 0 | K16: =J16*$K$4 -> 0 | L16: =(J16+K16)*C16 -> 0 | M16: =(J16+K16)*$M$4/(1-$M$4) -> 0 | N16: =M16+J16+K16 -> 0 | O16: =N16*C16 -> 0
B17: no | C17: 0 | D17: 0 | E17: =+C17*D17 -> 0 | F17: =IF(B17="si",D17*$F$4,0) -> 0 | G17: =(D17+F17)*$G$4 -> 0 | H17: =(D17+F17+G17)*$H$4 -> 0 | I17: =IF(B17="si",(D17+F17+G17+H17)*$I$4,0) -> 0 | J17: =D17+F17+G17+H17+I17 -> 0 | K17: =J17*$K$4 -> 0 | L17: =(J17+K17)*C17 -> 0 | M17: =(J17+K17)*$M$4/(1-$M$4) -> 0 | N17: =M17+J17+K17 -> 0 | O17: =N17*C17 -> 0
B18: no | C18: 0 | D18: 0 | E18: =+C18*D18 -> 0 | F18: =IF(B18="si",D18*$F$4,0) -> 0 | G18: =(D18+F18)*$G$4 -> 0 | H18: =(D18+F18+G18)*$H$4 -> 0 | I18: =IF(B18="si",(D18+F18+G18+H18)*$I$4,0) -> 0 | J18: =D18+F18+G18+H18+I18 -> 0 | K18: =J18*$K$4 -> 0 | L18: =(J18+K18)*C18 -> 0 | M18: =(J18+K18)*$M$4/(1-$M$4) -> 0 | N18: =M18+J18+K18 -> 0 | O18: =N18*C18 -> 0
A19: Sección 3
B20: no | C20: 0 | D20: 0 | E20: =+C20*D20 -> 0 | F20: =IF(B20="si",D20*$F$4,0) -> 0 | G20: =(D20+F20)*$G$4 -> 0 | H20: =(D20+F20+G20)*$H$4 -> 0 | I20: =IF(B20="si",(D20+F20+G20+H20)*$I$4,0) -> 0 | J20: =D20+F20+G20+H20+I20 -> 0 | K20: =J20*$K$4 -> 0 | L20: =(J20+K20)*C20 -> 0 | M20: =(J20+K20)*$M$4/(1-$M$4) -> 0 | N20: =M20+J20+K20 -> 0 | O20: =N20*C20 -> 0
D22: Total FOB | E22: =SUM(E6:E20) -> 0 | J22: Costo Nac. | L22: =SUM(L6:L20) -> 0 | N22: Total Venta | O22: =SUM(O6:O20) -> 0
N23: UTILIDAD | O23: =O22-L22 -> 0
A25: IMPORTADO
A26: si
A27: no

Sheet Productos 4
A1: MATRIZ DE COSTO PROYECTO: | E1: =+Equipos!E1 -> 0
A3: Productos 4 | F3: Transporte | G3: Seguros | H3: IVA | I3: DAI | J3: Costo Untit | K3: Administración | L3: Costo total | M3: Margen GV | N3: Precio Venta | O3: Precio Venta
A4: Description | C4: Qty | D4: Costo Unit | E4: Costo Total | F4: 0.1 | G4: 0 | H4: 0.13 | I4: 0.14 | J4: Nacionalizado | K4: 0.03 | L4: Nacionaliado | M4: 0.3 | N4: Unitario | O4: Total
A5: Sección 1 | B5: IMPORTADO
B6: no | C6: 0 | D6: 0 | E6: =+D6*C6 -> 0 | F6: =IF(B6="si",D6*$F$4,0) -> 0 | G6: =(D6+F6)*$G$4 -> 0 | H6: =(D6+F6+G6)*$H$4 -> 0 | I6: =IF(B6="si",(D6+F6+G6+H6)*$I$4,0) -> 0 | J6: =D6+F6+G6+H6+I6 -> 0 | K6: =J6*$K$4 -> 0 | L6: =(J6+K6)*C6 -> 0 | M6: =(J6+K6)*$M$4/(1-$M$4) -> 0 | N6: =M6+J6+K6 -> 0 | O6: =N6*C6 -> 0
B7: no | C7: 0 | D7: 0 | E7: =+D7*C7 -> 0 | F7: =IF(B7="si",D7*$F$4,0) -> 0 | G7: =(D7+F7)*$G$4 -> 0 | H7: =(D7+F7+G7)*$H$4 -> 0 | I7: =IF(B7="si",(D7+F7+G7+H7)*$I$4,0) -> 0 | J7: =D7+F7+G7+H7+I7 -> 0 | K7: =J7*$K$4 -> 0 | L7: =(J7+K7)*C7 -> 0 | M7: =(J7+K7)*$M$4/(1-$M$4) -> 0 | N7: =M7+J7+K7 -> 0 | O7: =N7*C7 -> 0
B8: no | C8: 0 | D8: 0 | E8: =+D8*C8 -> 0 | F8: =IF(B8="si",D8*$F$4,0) -> 0 | G8: =(D8+F8)*$G$4 -> 0 | H8: =(D8+F8+G8)*$H$4 -> 0 | I8: =IF(B8="si",(D8+F8+G8+H8)*$I$4,0) -> 0 | J8: =D8+F8+G8+H8+I8 -> 0 | K8: =J8*$K$4 -> 0 | L8: =(J8+K8)*C8 -> 0 | M8: =(J8+K8)*$M$4/(1-$M$4) -> 0 | N8: =M8+J8+K8 -> 0 | O8: =N8*C8 -> 0
B9: no | C9: 0 | D9: 0 | E9: =+D9*C9 -> 0 | F9: =IF(B9="si",D9*$F$4,0) -> 0 | G9: =(D9+F9)*$G$4 -> 0 | H9: =(D9+F9+G9)*$H$4 -> 0 | I9: =IF(B9="si",(D9+F9+G9+H9)*$I$4,0) -> 0 | J9: =D9+F9+G9+H9+I9 -> 0 | K9: =J9*$K$4 -> 0 | L9: =(J9+K9)*C9 -> 0 | M9: =(J9+K9)*$M$4/(1-$M$4) -> 0 | N9: =M9+J9+K9 -> 0 | O9: =N9*C9 -> 0
B10: no | C10: 0 | D10: 0 | E10: =+D10*C10 -> 0 | F10: =IF(B10="si",D10*$F$4,0) -> 0 | G10: =(D10+F10)*$G$4 -> 0 | H10: =(D10+F10+G10)*$H$4 -> 0 | I10: =IF(B10="si",(D10+F10+G10+H10)*$I$4,0) -> 0 | J10: =D10+F10+G10+H10+I10 -> 0 | K10: =J10*$K$4 -> 0 | L10: =(J10+K10)*C10 -> 0 | M10: =(J10+K10)*$M$4/(1-$M$4) -> 0 | N10: =M10+J10+K10 -> 0 | O10: =N10*C10 -> 0
B11: no | C11: 0 | D11: 0 | E11: =+D11*C11 -> 0 | F11: =IF(B11="si",D11*$F$4,0) -> 0 | G11: =(D11+F11)*$G$4 -> 0 | H11: =(D11+F11+G11)*$H$4 -> 0 | I11: =IF(B11="si",(D11+F11+G11+H11)*$I$4,0) -> 0 | J11: =D11+F11+G11+H11+I11 -> 0 | K11: =J11*$K$4 -> 0 | L11: =(J11+K11)*C11 -> 0 | M11: =(J11+K11)*$M$4/(1-$M$4) -> 0 | N11: =M11+J11+K11 -> 0 | O11: =N11*C11 -> 0
A12: Sección 2
B13: no | C13: 0 | D13: 0 | E13: =+C13*D13*(1-C22) -> 0 | F13: =IF(B13="si",D13*$F$4,0) -> 0 | G13: =(D13+F13)*$G$4 -> 0 | H13: =(D13+F13+G13)*$H$4 -> 0 | I13: =IF(B13="si",(D13+F13+G13+H13)*$I$4,0) -> 0 | J13: =D13+F13+G13+H13+I13 -> 0 | K13: =J13*$K$4 -> 0 | L13: =(J13+K13)*C13 -> 0 | M13: =(J13+K13)*$M$4/(1-$M$4) -> 0 | N13: =M13+J13+K13 -> 0 | O13: =N13*C13 -> 0
B14: no | C14: 0 | D14: 0 | E14: =+C14*D14 -> 0 | F14: =IF(B14="si",D14*$F$4,0) -> 0 | G14: =(D14+F14)*$G$4 -> 0 | H14: =(D14+F14+G14)*$H$4 -> 0 | I14: =IF(B14="si",(D14+F14+G14+H14)*$I$4,0) -> 0 | J14: =D14+F14+G14+H14+I14 -> 0 | K14: =J14*$K$4 -> 0 | L14: =(J14+K14)*C14 -> 0 | M14: =(J14+K14)*$M$4/(1-$M$4) -> 0 | N14: =M14+J14+K14 -> 0 | O14: =N14*C14 -> 0
B15: no | C15: 0 | D15: 0 | E15: =+C15*D15 -> 0 | F15: =IF(B15="si",D15*$F$4,0) -> 0 | G15: =(D15+F15)*$G$4 -> 0 | H15: =(D15+F15+G15)*$H$4 -> 0 | I15: =IF(B15="si",(D15+F15+G15+H15)*$I$4,0) -> 0 | J15: =D15+F15+G15+H15+I15 -> 0 | K15: =J15*$K$4 -> 0 | L15: =(J15+K15)*C15 -> 0 | M15: =(J15+K15)*$M$4/(1-$M$4) -> 0 | N15: =M15+J15+K15 -> 0 | O15: =N15*C15 -> 0
B16: no | C16: 0 | D16: 0 | E16: =+C16*D16 -> 0 | F16: =IF(B16="si",D16*$F$4,0) -> 0 | G16: =(D16+F16)*$G$4 -> 0 | H16: =(D16+F16+G16)*$H$4 -> 0 | I16: =IF(B16="si",(D16+F16+G16+H16)*$I$4,0) -> 0 | J16: =D16+F16+G16+H16+I16 -> 0 | K16: =J16*$K$4 -> 0 | L16: =(J16+K16)*C16 -> 0 | M16: =(J16+K16)*$M$4/(1-$M$4) -> 0 | N16: =M16+J16+K16 -> 0 | O16: =N16*C16 -> 0
B17: no | C17: 0 | D17: 0 | E17: =+C17*D17 -> 0 | F17: =IF(B17="si",D17*$F$4,0) -> 0 | G17: =(D17+F17)*$G$4 -> 0 | H17: =(D17+F17+G17)*$H$4 -> 0 | I17: =IF(B17="si",(D17+F17+G17+H17)*$I$4,0) -> 0 | J17: =D17+F17+G17+H17+I17 -> 0 | K17: =J17*$K$4 -> 0 | L17: =(J17+K17)*C17 -> 0 | M17: =(J17+K17)*$M$4/(1-$M$4) -> 0 | N17: =M17+J17+K17 -> 0 | O17: =N17*C17 -> 0
A18: Sección 3
B19: no | C19: 0 | D19: 0 | E19: =+C19*D19 -> 0 | F19: =IF(B19="si",D19*$F$4,0) -> 0 | G19: =(D19+F19)*$G$4 -> 0 | H19: =(D19+F19+G19)*$H$4 -> 0 | I19: =IF(B19="si",(D19+F19+G19+H19)*$I$4,0) -> 0 | J19: =D19+F19+G19+H19+I19 -> 0 | K19: =J19*$K$4 -> 0 | L19: =(J19+K19)*C19 -> 0 | M19: =(J19+K19)*$M$4/(1-$M$4) -> 0 | N19: =M19+J19+K19 -> 0 | O19: =N19*C19 -> 0
D21: Total FOB | E21: =SUM(E6:E19) -> 0 | J21: Costo Nac. | L21: =SUM(L6:L19) -> 0 | N21: Total Venta | O21: =SUM(O6:O19) -> 0
N22: UTILIDAD | O22: =O21-L21 -> 0
A24: IMPORTADO
A25: si
A26: no

Sheet Productos 5
A1: MATRIZ DE COSTO PROYECTO: | E1: =+Equipos!E1 -> 0
A3: Productos 5 | F3: Transporte | G3: Seguros | H3: IVA | I3: DAI | J3: Costo Untit | K3: Administración | L3: Costo total | M3: Margen GV | N3: Precio Venta | O3: Precio Venta
A4: Description | C4: Qty | D4: Costo Unit | E4: Costo Total | F4: 0.1 | G4: 0 | H4: 0.13 | I4: 0.14 | J4: Nacionalizado | K4: 0.03 | L4: Nacionaliado | M4: 0.3 | N4: Unitario | O4: Total
A5: SERVERS | B5: IMPORTADO
B6: no | C6: 0 | D6: 0 | E6: =+D6*C6 -> 0 | F6: =IF(B6="si",D6*$F$4,0) -> 0 | G6: 0 | H6: =(D6+F6+G6)*$H$4 -> 0 | I6: =IF(B6="si",(D6+F6+G6+H6)*$I$4,0) -> 0 | J6: =D6+F6+G6+H6+I6 -> 0 | K6: =J6*$K$4 -> 0 | L6: =(J6+K6)*C6 -> 0 | M6: =(J6+K6)*$M$4/(1-$M$4) -> 0 | N6: =M6+J6+K6 -> 0 | O6: =N6*C6 -> 0
B7: no | C7: 0 | D7: 0 | E7: =+D7*C7 -> 0 | F7: =IF(B7="si",D7*$F$4,0) -> 0 | G7: =(D7+F7)*$G$4 -> 0 | H7: =(D7+F7+G7)*$H$4 -> 0 | I7: =IF(B7="si",(D7+F7+G7+H7)*$I$4,0) -> 0 | J7: =D7+F7+G7+H7+I7 -> 0 | K7: =J7*$K$4 -> 0 | L7: =(J7+K7)*C7 -> 0 | M7: =(J7+K7)*$M$4/(1-$M$4) -> 0 | N7: =M7+J7+K7 -> 0 | O7: =N7*C7 -> 0
B8: no | C8: 0 | D8: 0 | E8: =+D8*C8 -> 0 | F8: =IF(B8="si",D8*$F$4,0) -> 0 | G8: =(D8+F8)*$G$4 -> 0 | H8: =(D8+F8+G8)*$H$4 -> 0 | I8: =IF(B8="si",(D8+F8+G8+H8)*$I$4,0) -> 0 | J8: =D8+F8+G8+H8+I8 -> 0 | K8: =J8*$K$4 -> 0 | L8: =(J8+K8)*C8 -> 0 | M8: =(J8+K8)*$M$4/(1-$M$4) -> 0 | N8: =M8+J8+K8 -> 0 | O8: =N8*C8 -> 0
B9: no | C9: 0 | D9: 0 | E9: =+D9*C9 -> 0 | F9: =IF(B9="si",D9*$F$4,0) -> 0 | G9: =(D9+F9)*$G$4 -> 0 | H9: =(D9+F9+G9)*$H$4 -> 0 | I9: =IF(B9="si",(D9+F9+G9+H9)*$I$4,0) -> 0 | J9: =D9+F9+G9+H9+I9 -> 0 | K9: =J9*$K$4 -> 0 | L9: =(J9+K9)*C9 -> 0 | M9: =(J9+K9)*$M$4/(1-$M$4) -> 0 | N9: =M9+J9+K9 -> 0 | O9: =N9*C9 -> 0
B10: no | C10: 0 | D10: 0 | E10: =+D10*C10 -> 0 | F10: =IF(B10="si",D10*$F$4,0) -> 0 | G10: =(D10+F10)*$G$4 -> 0 | H10: =(D10+F10+G10)*$H$4 -> 0 | I10: =IF(B10="si",(D10+F10+G10+H10)*$I$4,0) -> 0 | J10: =D10+F10+G10+H10+I10 -> 0 | K10: =J10*$K$4 -> 0 | L10: =(J10+K10)*C10 -> 0 | M10: =(J10+K10)*$M$4/(1-$M$4) -> 0 | N10: =M10+J10+K10 -> 0 | O10: =N10*C10 -> 0
B11: no | C11: 0 | D11: 0 | E11: =+D11*C11 -> 0 | F11: =IF(B11="si",D11*$F$4,0) -> 0 | G11: =(D11+F11)*$G$4 -> 0 | H11: =(D11+F11+G11)*$H$4 -> 0 | I11: =IF(B11="si",(D11+F11+G11+H11)*$I$4,0) -> 0 | J11: =D11+F11+G11+H11+I11 -> 0 | K11: =J11*$K$4 -> 0 | L11: =(J11+K11)*C11 -> 0 | M11: =(J11+K11)*$M$4/(1-$M$4) -> 0 | N11: =M11+J11+K11 -> 0 | O11: =N11*C11 -> 0
A12: Sección 2
B13: no | C13: 0 | D13: 0 | E13: =+C13*D13 -> 0 | F13: =IF(B13="si",D13*$F$4,0) -> 0 | G13: =(D13+F13)*$G$4 -> 0 | H13: =(D13+F13+G13)*$H$4 -> 0 | I13: =IF(B13="si",(D13+F13+G13+H13)*$I$4,0) -> 0 | J13: =D13+F13+G13+H13+I13 -> 0 | K13: =J13*$K$4 -> 0 | L13: =(J13+K13)*C13 -> 0 | M13: =(J13+K13)*$M$4/(1-$M$4) -> 0 | N13: =M13+J13+K13 -> 0 | O13: =N13*C13 -> 0
B14: no | C14: 0 | D14: 0 | E14: =+C14*D14 -> 0 | F14: =IF(B14="si",D14*$F$4,0) -> 0 | G14: =(D14+F14)*$G$4 -> 0 | H14: =(D14+F14+G14)*$H$4 -> 0 | I14: =IF(B14="si",(D14+F14+G14+H14)*$I$4,0) -> 0 | J14: =D14+F14+G14+H14+I14 -> 0 | K14: =J14*$K$4 -> 0 | L14: =(J14+K14)*C14 -> 0 | M14: =(J14+K14)*$M$4/(1-$M$4) -> 0 | N14: =M14+J14+K14 -> 0 | O14: =N14*C14 -> 0
B15: no | C15: 0 | D15: 0 | E15: =+C15*D15 -> 0 | F15: =IF(B15="si",D15*$F$4,0) -> 0 | G15: =(D15+F15)*$G$4 -> 0 | H15: =(D15+F15+G15)*$H$4 -> 0 | I15: =IF(B15="si",(D15+F15+G15+H15)*$I$4,0) -> 0 | J15: =D15+F15+G15+H15+I15 -> 0 | K15: =J15*$K$4 -> 0 | L15: =(J15+K15)*C15 -> 0 | M15: =(J15+K15)*$M$4/(1-$M$4) -> 0 | N15: =M15+J15+K15 -> 0 | O15: =N15*C15 -> 0
B16: no | C16: 0 | D16: 0 | E16: =+C16*D16 -> 0 | F16: =IF(B16="si",D16*$F$4,0) -> 0 | G16: =(D16+F16)*$G$4 -> 0 | H16: =(D16+F16+G16)*$H$4 -> 0 | I16: =IF(B16="si",(D16+F16+G16+H16)*$I$4,0) -> 0 | J16: =D16+F16+G16+H16+I16 -> 0 | K16: =J16*$K$4 -> 0 | L16: =(J16+K16)*C16 -> 0 | M16: =(J16+K16)*$M$4/(1-$M$4) -> 0 | N16: =M16+J16+K16 -> 0 | O16: =N16*C16 -> 0
B17: no | C17: 0 | D17: 0 | E17: =+C17*D17 -> 0 | F17: =IF(B17="si",D17*$F$4,0) -> 0 | G17: =(D17+F17)*$G$4 -> 0 | H17: =(D17+F17+G17)*$H$4 -> 0 | I17: =IF(B17="si",(D17+F17+G17+H17)*$I$4,0) -> 0 | J17: =D17+F17+G17+H17+I17 -> 0 | K17: =J17*$K$4 -> 0 | L17: =(J17+K17)*C17 -> 0 | M17: =(J17+K17)*$M$4/(1-$M$4) -> 0 | N17: =M17+J17+K17 -> 0 | O17: =N17*C17 -> 0
B18: no | C18: 0 | D18: 0 | E18: =+C18*D18 -> 0 | F18: =IF(B18="si",D18*$F$4,0) -> 0 | G18: =(D18+F18)*$G$4 -> 0 | H18: =(D18+F18+G18)*$H$4 -> 0 | I18: =IF(B18="si",(D18+F18+G18+H18)*$I$4,0) -> 0 | J18: =D18+F18+G18+H18+I18 -> 0 | K18: =J18*$K$4 -> 0 | L18: =(J18+K18)*C18 -> 0 | M18: =(J18+K18)*$M$4/(1-$M$4) -> 0 | N18: =M18+J18+K18 -> 0 | O18: =N18*C18 -> 0
B19: no | C19: 0 | D19: 0 | E19: =+C19*D19 -> 0 | F19: =IF(B19="si",D19*$F$4,0) -> 0 | G19: =(D19+F19)*$G$4 -> 0 | H19: =(D19+F19+G19)*$H$4 -> 0 | I19: =IF(B19="si",(D19+F19+G19+H19)*$I$4,0) -> 0 | J19: =D19+F19+G19+H19+I19 -> 0 | K19: =J19*$K$4 -> 0 | L19: =(J19+K19)*C19 -> 0 | M19: =(J19+K19)*$M$4/(1-$M$4) -> 0 | N19: =M19+J19+K19 -> 0 | O19: =N19*C19 -> 0
B20: no | C20: 0 | D20: 0 | E20: =+C20*D20 -> 0 | F20: =IF(B20="si",D20*$F$4,0) -> 0 | G20: =(D20+F20)*$G$4 -> 0 | H20: =(D20+F20+G20)*$H$4 -> 0 | I20: =IF(B20="si",(D20+F20+G20+H20)*$I$4,0) -> 0 | J20: =D20+F20+G20+H20+I20 -> 0 | K20: =J20*$K$4 -> 0 | L20: =(J20+K20)*C20 -> 0 | M20: =(J20+K20)*$M$4/(1-$M$4) -> 0 | N20: =M20+J20+K20 -> 0 | O20: =N20*C20 -> 0
B21: no | C21: 0 | D21: 0 | E21: =+C21*D21 -> 0 | F21: =IF(B21="si",D21*$F$4,0) -> 0 | G21: =(D21+F21)*$G$4 -> 0 | H21: =(D21+F21+G21)*$H$4 -> 0 | I21: =IF(B21="si",(D21+F21+G21+H21)*$I$4,0) -> 0 | J21: =D21+F21+G21+H21+I21 -> 0 | K21: =J21*$K$4 -> 0 | L21: =(J21+K21)*C21 -> 0 | M21: =(J21+K21)*$M$4/(1-$M$4) -> 0 | N21: =M21+J21+K21 -> 0 | O21: =N21*C21 -> 0
A22: Sección 3
B23: no | C23: 0 | D23: 0 | E23: =+C23*D23 -> 0 | F23: =IF(B23="si",D23*$F$4,0) -> 0 | G23: =(D23+F23)*$G$4 -> 0 | H23: =(D23+F23+G23)*$H$4 -> 0 | I23: =IF(B23="si",(D23+F23+G23+H23)*$I$4,0) -> 0 | J23: =D23+F23+G23+H23+I23 -> 0 | K23: =J23*$K$4 -> 0 | L23: =(J23+K23)*C23 -> 0 | M23: =(J23+K23)*$M$4/(1-$M$4) -> 0 | N23: =M23+J23+K23 -> 0 | O23: =N23*C23 -> 0
D25: Total FOB | E25: =SUM(E6:E23) -> 0 | J25: Costo Nac. | L25: =SUM(L6:L23) -> 0 | N25: Total Venta | O25: =SUM(O6:O23) -> 0
N26: UTILIDAD | O26: =O25-L25 -> 0
A28: IMPORTADO
A29: si
A30: no

Sheet MATERIALES
A1: MATRIZ DE COSTO PROYECTO:
A3: Materiales | F3: Transporte | G3: Seguros | H3: IVA | I3: DAI | J3: Costo Untit | K3: Administración | L3: Costo total | M3: Margen GV | N3: Precio Venta | O3: Precio Venta | P3: Financ.
A4: Description | C4: Qty | D4: Costo Unit | E4: Costo Total | F4: 0.1 | G4: 0 | H4: 0.13 | I4: 0.14 | J4: Nacionalizado | K4: 0.03 | L4: Nacionaliado | M4: 0.3 | N4: Unitario | O4: Total
A5: Sección 1 | B5: IMPORTADO
A6: caja nema para SENSORES | B6: si | C6: 0 | D6: 0 | E6: =+D6*C6 -> 0 | F6: =IF(B6="si",D6*$F$4,0) -> 0 | G6: 0 | H6: =(D6+F6+G6)*$H$4 -> 0 | I6: =IF(B6="si",(D6+F6+G6+H6)*$I$4,0) -> 0 | J6: =D6+F6+G6+H6+I6 -> 0 | K6: =J6*$K$4 -> 0 | L6: =(J6+K6)*C6 -> 0 | M6: =(J6+K6)*$M$4/(1-$M$4) -> 0 | N6: =M6+J6+K6 -> 0 | O6: =N6*C6 -> 0
A7: Cable UTP cat6A Exteriores caja | B7: si | C7: 0 | D7: 0 | E7: =+D7*C7 -> 0 | F7: =IF(B7="si",D7*$F$4,0) -> 0 | G7: =(D7+F7)*$G$4 -> 0 | H7: =(D7+F7+G7)*$H$4 -> 0 | I7: =IF(B7="si",(D7+F7+G7+H7)*$I$4,0) -> 0 | J7: =D7+F7+G7+H7+I7 -> 0 | K7: =J7*$K$4 -> 0 | L7: =(J7+K7)*C7 -> 0 | M7: =(J7+K7)*$M$4/(1-$M$4) -> 0 | N7: =M7+J7+K7 -> 0 | O7: =N7*C7 -> 0
A8: Cable UTP cat6A Exteriores | B8: si | C8: 0 | D8: 0 | E8: =+D8*C8 -> 0 | F8: =IF(B8="si",D8*$F$4,0) -> 0 | G8: =(D8+F8)*$G$4 -> 0 | H8: =(D8+F8+G8)*$H$4 -> 0 | I8: =IF(B8="si",(D8+F8+G8+H8)*$I$4,0) -> 0 | J8: =D8+F8+G8+H8+I8 -> 0 | K8: =J8*$K$4 -> 0 | L8: =(J8+K8)*C8 -> 0 | M8: =(J8+K8)*$M$4/(1-$M$4) -> 0 | N8: =M8+J8+K8 -> 0 | O8: =N8*C8 -> 0
A9: conectores rj45 cat 6 | B9: si | C9: 0 | D9: 0 | E9: =+D9*C9 -> 0 | F9: =IF(B9="si",D9*$F$4,0) -> 0 | H9: =(D9+F9+G9)*$H$4 -> 0 | I9: =IF(B9="si",(D9+F9+G9+H9)*$I$4,0) -> 0 | J9: =D9+F9+G9+H9+I9 -> 0 | K9: =J9*$K$4 -> 0 | L9: =(J9+K9)*C9 -> 0 | M9: =(J9+K9)*$M$4/(1-$M$4) -> 0 | N9: =M9+J9+K9 -> 0 | O9: =N9*C9 -> 0
A10: cable electrico #12 rojo | B10: si | C10: 0 | D10: 0 | E10: =+D10*C10 -> 0 | F10: =IF(B10="si",D10*$F$4,0) -> 0 | G10: =(D10+F10)*$G$4 -> 0 | H10: =(D10+F10+G10)*$H$4 -> 0 | I10: =IF(B10="si",(D10+F10+G10+H10)*$I$4,0) -> 0 | J10: =D10+F10+G10+H10+I10 -> 0 | K10: =J10*$K$4 -> 0 | L10: =(J10+K10)*C10 -> 0 | M10: =(J10+K10)*$M$4/(1-$M$4) -> 0 | N10: =M10+J10+K10 -> 0 | O10: =N10*C10 -> 0
A11: cable electrico #12 blanco | B11: si | C11: 0 | D11: 0 | E11: =+D11*C11 -> 0 | F11: =IF(B11="si",D11*$F$4,0) -> 0 | G11: =(D11+F11)*$G$4 -> 0 | H11: =(D11+F11+G11)*$H$4 -> 0 | I11: =IF(B11="si",(D11+F11+G11+H11)*$I$4,0) -> 0 | J11: =D11+F11+G11+H11+I11 -> 0 | K11: =J11*$K$4 -> 0 | L11: =(J11+K11)*C11 -> 0 | M11: =(J11+K11)*$M$4/(1-$M$4) -> 0 | N11: =M11+J11+K11 -> 0 | O11: =N11*C11 -> 0
A12: cable electrico #12 verde | B12: si | C12: 0 | D12: 0 | E12: =+D12*C12 -> 0 | F12: =IF(B12="si",D12*$F$4,0) -> 0 | G12: =(D12+F12)*$G$4 -> 0 | H12: =(D12+F12+G12)*$H$4 -> 0 | I12: =IF(B12="si",(D12+F12+G12+H12)*$I$4,0) -> 0 | J12: =D12+F12+G12+H12+I12 -> 0 | K12: =J12*$K$4 -> 0 | L12: =(J12+K12)*C12 -> 0 | M12: =(J12+K12)*$M$4/(1-$M$4) -> 0 | N12: =M12+J12+K12 -> 0 | O12: =N12*C12 -> 0
